Workbook

Sheet DATABANK
A1: Count | B1: Item Number | C1: POSITION | D1: Specialist | E1: Parentetical | F1: UNIT / SECTION | G1: CADRE | H1: 26 | I1: SALARY GRADE | J1: AUTHORIZED SALARY | K1: Level2 | L1: FILLED&UNFILLED | M1: LAST | N1: FIRST | O1: MIDDLE | P1: SUFFIX | Q1: DATE OF BIRTH | R1: DATE OF ORIGINAL APPOINTMENT | S1: ASSUMPTION | T1: LATEST PROMOTION | U1: CIVIL STATUS | V1: GENDER | W1: AGE | X1: AGE GROUP | Y1: PLACE OF BIRTH | Z1: No., Street, Subd./Village | AA1: Baranggay | AB1: City/Municipality | AC1: Province | AD1: Zip Code | AE1: EDUCATIONAL ATTAINMENT | AF1: PROGRAM/COURSE | AG1: ELIGIBILITY | AH1: LICENSE NO. | AI1: VALIDITY | AJ1: GSIS | AK1: PAG-IBIG | AL1: PHILHEALTH | AM1: TIN | AN1: MOBILE NO. | AO1: PHONE NO. | AP1: EMAIL ADDRESS
A2: 1 | B2: OSEC-DOHB-MDC2-29-2025 | C2: Medical Center Chief II | E2: Medical Center Chief | F2: Office of the Medical Center Chief | G2: Physician | H2: Medical Division | I2: 27 | J2: =LOOKUP(Table1[[#This Row],[SALARY GRADE]],{1,2,3,4,5,6,7,8,9,10,11,12,13,14,15,16,17,18,19,20,21,22,23,24,25,26,27,28,29,30,31,32,33},{14364,15522,16486,17506,18581,19716,20914,22423,24329,26917,31705,33947,36125,38764,42178,45694,49562,53818,59153,66052,73303,81796,91306,102603,116643,131807,148940,167129,187531,210718,300961,356237,449157}) -> 148940 | K2: 3rd | L2: =IF(Table1[[#This Row],[LAST]]="","Unfilled","Filled") -> Filled | M2: Rubiano | N2: Ruby Ephraim | O2: Morales | Q2: 24172 | R2: 42019 | S2: 45061 | T2: 45061 | U2: Married | V2: Male | W2: =DATEDIF(Q2,TODAY(),"Y") -> 60 | X2: =IF(ABS(Table1[[#This Row],[AGE]])>59,"60 and above",IF(ABS(Table1[[#This Row],[AGE]])>49,"50-59",IF(ABS(Table1[[#This Row],[AGE]])>39,"40-49",IF(ABS(Table1[[#This Row],[AGE]])>29,"30-39",IF(ABS(Table1[[#This Row],[AGE]])>19,"20-29",""))))) -> 60 and above | Y2: Samal, Bataan | Z2: #99 K 2nd | AA2: Kamuning | AB2: Quezon City | AC2: Metro Manila | AD2: 1103 | AE2: Doctor of Medicine | AF2: Medicine | AG2: RA 1080 | AH2: 0077906 | AI2: 46452 | AJ2: 2001913799 | AK2: 1211-8088-4348 | AL2: 0700-0120-7464 | AM2: 164-003-877 | AN2: 0926-671-5623 | AO2: N/A | AP2: rer.rubiano@gmail.com
A3: 2 | B3: OSEC-DOHB-COMPS2-30-2025 | C3: Chief of Medical professional Staff II | D3: Obstetrician | E3: CMPS | F3: Office of the Chief of Medical Professional Staff | G3: Physician | H3: Medical Division | I3: 26 | J3: =LOOKUP(Table1[[#This Row],[SALARY GRADE]],{1,2,3,4,5,6,7,8,9,10,11,12,13,14,15,16,17,18,19,20,21,22,23,24,25,26,27,28,29,30,31,32,33},{14364,15522,16486,17506,18581,19716,20914,22423,24329,26917,31705,33947,36125,38764,42178,45694,49562,53818,59153,66052,73303,81796,91306,102603,116643,131807,148940,167129,187531,210718,300961,356237,449157}) -> 131807 | K3: 3rd | L3: =IF(Table1[[#This Row],[LAST]]="","Unfilled","Filled") -> Filled | M3: Gabor | N3: Rebecca Ann | O3: Vasquez | Q3: 30144 | R3: 44363 | S3: 44363 | T3: 45505 | U3: Single | V3: Female | W3: =DATEDIF(Q3,TODAY(),"Y") -> 44 | X3: =IF(ABS(Table1[[#This Row],[AGE]])>59,"60 and above",IF(ABS(Table1[[#This Row],[AGE]])>49,"50-59",IF(ABS(Table1[[#This Row],[AGE]])>39,"40-49",IF(ABS(Table1[[#This Row],[AGE]])>29,"30-39",IF(ABS(Table1[[#This Row],[AGE]])>19,"20-29",""))))) -> 40-49 | Y3: Makati City | Z3: 115 Camino Real Rd., Pilar Village | AA3: Pilar | AB3: Las Piñas City | AC3: NCR | AD3: 1740 | AE3: Doctor of Medicine | AF3: Medicine | AG3: RA 1080 | AH3: 0110711 | AI3: 45850 | AJ3: 2004118248 | AK3: 1212-7910-9885 | AL3: 0800-0096-7290 | AM3: 219-078-812 | AN3: 0917-826-0712 | AO3: (02) 8818-1298 | AP3: rebeccaanngabormd@gmail.com
A4: 3 | B4: OSEC-DOHB-MDSP3-270008-2022 | C4: Medical Specialist III (Internal Medicine) | D4: Internist | E4: Medical Specialist III | F4: Internal Medicine Department | G4: Physician | H4: Medical Division | I4: 24 | J4: =LOOKUP(Table1[[#This Row],[SALARY GRADE]],{1,2,3,4,5,6,7,8,9,10,11,12,13,14,15,16,17,18,19,20,21,22,23,24,25,26,27,28,29,30,31,32,33},{14364,15522,16486,17506,18581,19716,20914,22423,24329,26917,31705,33947,36125,38764,42178,45694,49562,53818,59153,66052,73303,81796,91306,102603,116643,131807,148940,167129,187531,210718,300961,356237,449157}) -> 102603 | K4: 2nd | L4: =IF(Table1[[#This Row],[LAST]]="","Unfilled","Filled") -> Filled | M4: Demetria | N4: Jessie | O4: Datig | Q4: 28721 | R4: 44858 | S4: 44858 | T4: 44858 | U4: Married | V4: Male | W4: =DATEDIF(Q4,TODAY(),"Y") -> 47 | X4: =IF(ABS(Table1[[#This Row],[AGE]])>59,"60 and above",IF(ABS(Table1[[#This Row],[AGE]])>49,"50-59",IF(ABS(Table1[[#This Row],[AGE]])>39,"40-49",IF(ABS(Table1[[#This Row],[AGE]])>29,"30-39",IF(ABS(Table1[[#This Row],[AGE]])>19,"20-29",""))))) -> 40-49 | Y4: Leyte | Z4: B25 L20 P2 Baby's Breath St., Villa de Primarosa | AA4: Buhay na Tubig | AB4: Imus City | AC4: Cavite | AD4: 4103 | AE4: Doctor of Medicine | AF4: Medicine | AG4: RA 1080 | AH4: 0106098 | AI4: 46253 | AJ4: 2001127858 | AK4: 1210-0608-1771 | AL4: 0300-0227-2284 | AM4: 249-490-097 | AN4: 0925-688-8340 | AO4: (046) 476-9635 | AP4: jesdm3a@gmail.com
A5: 4 | B5: OSEC-DOHB-MDSP3-270009-2022 | C5: Medical Specialist III (Surgeon) | D5: Surgeon | E5: Medical Specialist III | F5: Surgery Department | G5: Physician | H5: Medical Division | I5: 24 | J5: =LOOKUP(Table1[[#This Row],[SALARY GRADE]],{1,2,3,4,5,6,7,8,9,10,11,12,13,14,15,16,17,18,19,20,21,22,23,24,25,26,27,28,29,30,31,32,33},{14364,15522,16486,17506,18581,19716,20914,22423,24329,26917,31705,33947,36125,38764,42178,45694,49562,53818,59153,66052,73303,81796,91306,102603,116643,131807,148940,167129,187531,210718,300961,356237,449157}) -> 102603 | K5: 2nd | L5: =IF(Table1[[#This Row],[LAST]]="","Unfilled","Filled") -> Filled | M5: Sabal | N5: Eliseo | O5: Bautista | P5: Jr. | Q5: 26382 | R5: 44907 | S5: 44907 | T5: 44907 | U5: Married | V5: Male | W5: =DATEDIF(Q5,TODAY(),"Y") -> 54 | X5: =IF(ABS(Table1[[#This Row],[AGE]])>59,"60 and above",IF(ABS(Table1[[#This Row],[AGE]])>49,"50-59",IF(ABS(Table1[[#This Row],[AGE]])>39,"40-49",IF(ABS(Table1[[#This Row],[AGE]])>29,"30-39",IF(ABS(Table1[[#This Row],[AGE]])>19,"20-29",""))))) -> 50-59 | Y5: California, USA | Z5: 663 Arcedera, San Antonio | AA5: 43 | AB5: Cavite City | AC5: Cavite | AD5: 4100 | AE5: Doctor of Medicine | AF5: Medicine | AG5: RA 1080 | AH5: 0090301 | AI5: 45740 | AJ5: 2001006475 | AK5: 1213-1329-9128 | AL5: 1300-0500-7833 | AM5: 215-487-799 | AN5: 0917-551-2270 | AO5: (046) 434-17533 | AP5: leejaymd@gmail.com
A6: 5 | B6: OSEC-DOHB-MDSP3-270010-2022 | C6: Medical Specialist III (Anesthesiologist) | D6: Anesthesiologist | E6: Medical Specialist III | F6: Anesthesiology Department | G6: Physician | H6: Medical Division | I6: 24 | J6: =LOOKUP(Table1[[#This Row],[SALARY GRADE]],{1,2,3,4,5,6,7,8,9,10,11,12,13,14,15,16,17,18,19,20,21,22,23,24,25,26,27,28,29,30,31,32,33},{14364,15522,16486,17506,18581,19716,20914,22423,24329,26917,31705,33947,36125,38764,42178,45694,49562,53818,59153,66052,73303,81796,91306,102603,116643,131807,148940,167129,187531,210718,300961,356237,449157}) -> 102603 | K6: 2nd | L6: =IF(Table1[[#This Row],[LAST]]="","Unfilled","Filled") -> Filled | M6: Esguerra | N6: Marc Wilmer | O6: Dela Cruz | Q6: 32209 | R6: 44851 | S6: 44851 | T6: 44851 | U6: Married | V6: Male | W6: =DATEDIF(Q6,TODAY(),"Y") -> 38 | X6: =IF(ABS(Table1[[#This Row],[AGE]])>59,"60 and above",IF(ABS(Table1[[#This Row],[AGE]])>49,"50-59",IF(ABS(Table1[[#This Row],[AGE]])>39,"40-49",IF(ABS(Table1[[#This Row],[AGE]])>29,"30-39",IF(ABS(Table1[[#This Row],[AGE]])>19,"20-29",""))))) -> 30-39 | Y6: Las Piñas City | Z6: B3 L2 Redbay Ave. Norfolk Ridge, Greenwoods | AA6: Sampaloc 3 | AB6: Dasmariñas City | AC6: Cavite | AD6: 4114 | AE6: Doctor of Medicine | AF6: Medicine | AG6: RA 1080 | AH6: 0127400 | AI6: 46206 | AJ6: 2004685518 | AK6: 1211-4378-4931 | AL6: 0200-0252-3966 | AM6: 457-755-367 | AN6: 0949-825-7967 | AO6: N/A | AP6: mawiesguerra787@gmail.com
A7: 6 | B7: OSEC-DOHB-MDSP3-270011-2022 | C7: Medical Specialist III (Pediatrician) | D7: Pediatrician | E7: Medical Specialist III | F7: Pediatrics Department | G7: Physician | H7: Medical Division | I7: 24 | J7: =LOOKUP(Table1[[#This Row],[SALARY GRADE]],{1,2,3,4,5,6,7,8,9,10,11,12,13,14,15,16,17,18,19,20,21,22,23,24,25,26,27,28,29,30,31,32,33},{14364,15522,16486,17506,18581,19716,20914,22423,24329,26917,31705,33947,36125,38764,42178,45694,49562,53818,59153,66052,73303,81796,91306,102603,116643,131807,148940,167129,187531,210718,300961,356237,449157}) -> 102603 | K7: 2nd | L7: =IF(Table1[[#This Row],[LAST]]="","Unfilled","Filled") -> Filled | M7: Co | N7: Icene Rose | O7: Sy | Q7: 32445 | R7: 44837 | S7: 44837 | T7: 44837 | U7: Married | V7: Female | W7: =DATEDIF(Q7,TODAY(),"Y") -> 37 | X7: =IF(ABS(Table1[[#This Row],[AGE]])>59,"60 and above",IF(ABS(Table1[[#This Row],[AGE]])>49,"50-59",IF(ABS(Table1[[#This Row],[AGE]])>39,"40-49",IF(ABS(Table1[[#This Row],[AGE]])>29,"30-39",IF(ABS(Table1[[#This Row],[AGE]])>19,"20-29",""))))) -> 30-39 | Y7: Quezon City | Z7: 3517 Pacific Regency Cityland | AA7: 719 | AB7: Malate | AC7: Manila | AE7: Doctor of Medicine | AF7: Medicine | AG7: RA 1080 | AH7: 0129259 | AI7: 46689 | AJ7: 2006160496 | AK7: 1213-0852-8116 | AL7: 1501-1845-4002 | AM7: 494-339-885 | AN7: 0917-132-7204 | AO7: (02) 8372-9556 | AP7: icenerosesy@gmail.com
A8: 7 | B8: OSEC-DOHB-MDSP3-270012-2022 | C8: Medical Specialist III (Pathologist) | D8: Pathologist | E8: Medical Specialist III | F8: Clinical and Anatomical Laboratory Department | G8: Physician | H8: Medical Division | I8: 24 | J8: =LOOKUP(Table1[[#This Row],[SALARY GRADE]],{1,2,3,4,5,6,7,8,9,10,11,12,13,14,15,16,17,18,19,20,21,22,23,24,25,26,27,28,29,30,31,32,33},{14364,15522,16486,17506,18581,19716,20914,22423,24329,26917,31705,33947,36125,38764,42178,45694,49562,53818,59153,66052,73303,81796,91306,102603,116643,131807,148940,167129,187531,210718,300961,356237,449157}) -> 102603 | K8: 2nd | L8: =IF(Table1[[#This Row],[LAST]]="","Unfilled","Filled") -> Filled | M8: Rosales | N8: Carole Zaidel | O8: Marudo | Q8: 32426 | R8: 44762 | S8: 45323 | T8: 45323 | U8: Single | V8: Female | W8: =DATEDIF(Q8,TODAY(),"Y") -> 37 | X8: =IF(ABS(Table1[[#This Row],[AGE]])>59,"60 and above",IF(ABS(Table1[[#This Row],[AGE]])>49,"50-59",IF(ABS(Table1[[#This Row],[AGE]])>39,"40-49",IF(ABS(Table1[[#This Row],[AGE]])>29,"30-39",IF(ABS(Table1[[#This Row],[AGE]])>19,"20-29",""))))) -> 30-39 | Y8: Batangas City | Z8: #519 Garnet Bldg., Rosewood Pointe, Acacia Estate | AA8: Ususan | AB8: Taguig City | AC8: Metro Manila | AD8: 1639 | AE8: Doctor of Medicine | AF8: Medicine | AG8: RA 1080 | AH8: 0134392 | AI8: 45940 | AJ8: 2005378321 | AK8: 1210-4849-5669 | AL8: 0205-0559-7703 | AM8: 275-580-443 | AN8: 0927-235-9111 | AO8: 784-3268 | AP8: czaidelmrosales@gmail.com
A9: 8 | B9: OSEC-DOHB-MDSP3-270013-2022 | C9: Medical Specialist III (ER) | D9: Emergency Med | E9: Medical Specialist III | F9: Emergency Medicine Department | G9: Physician | H9: Medical Division | I9: 24 | J9: =LOOKUP(Table1[[#This Row],[SALARY GRADE]],{1,2,3,4,5,6,7,8,9,10,11,12,13,14,15,16,17,18,19,20,21,22,23,24,25,26,27,28,29,30,31,32,33},{14364,15522,16486,17506,18581,19716,20914,22423,24329,26917,31705,33947,36125,38764,42178,45694,49562,53818,59153,66052,73303,81796,91306,102603,116643,131807,148940,167129,187531,210718,300961,356237,449157}) -> 102603 | K9: 2nd | L9: =IF(Table1[[#This Row],[LAST]]="","Unfilled","Filled") -> Filled | M9: Napuli | N9: Brylle | O9: Siva | Q9: 32280 | R9: 44966 | S9: 45302 | T9: 45302 | U9: Single | V9: Male | W9: =DATEDIF(Q9,TODAY(),"Y") -> 38 | X9: =IF(ABS(Table1[[#This Row],[AGE]])>59,"60 and above",IF(ABS(Table1[[#This Row],[AGE]])>49,"50-59",IF(ABS(Table1[[#This Row],[AGE]])>39,"40-49",IF(ABS(Table1[[#This Row],[AGE]])>29,"30-39",IF(ABS(Table1[[#This Row],[AGE]])>19,"20-29",""))))) -> 30-39 | Y9: Las Piñas City | Z9: 410 Topaz St., Perpetual Village IV | AA9: Panapaan VIII | AB9: Bacoor City | AC9: Cavite | AD9: 4102 | AE9: Doctor of Medicine | AF9: Medicine | AG9: RA 1080 | AH9: 0129029 | AI9: 46159 | AJ9: 2006264724 | AK9: 1213-1628-3544 | AL9: 0802-6285-3733 | AM9: 459-479-355 | AN9: 0908-626-4633 | AO9: N/A | AP9: napulibrylle@yahoo.com
A10: 9 | B10: OSEC-DOHB-MDSPT3-270001-2022 | C10: Medical Specialist III (Part-time) (Pediatric Intensivist) | D10: Pediatric Intensivist | E10: Medical Specialist III | F10: Pediatrics Department | G10: Physician | H10: Medical Division | I10: 24 | J10: =LOOKUP(Table1[[#This Row],[SALARY GRADE]],{1,2,3,4,5,6,7,8,9,10,11,12,13,14,15,16,17,18,19,20,21,22,23,24,25,26,27,28,29,30,31,32,33},{14364,15522,16486,17506,18581,19716,20914,22423,24329,26917,31705,33947,36125,38764,42178,45694,49562,53818,59153,66052,73303,81796,91306,102603,116643,131807,148940,167129,187531,210718,300961,356237,449157}) -> 102603 | K10: 2nd | L10: =IF(Table1[[#This Row],[LAST]]="","Unfilled","Filled") -> Filled | M10: Fabian | N10: Bethzaida Rachel | O10: Saputil | Q10: 30063 | R10: 45027 | S10: 45027 | T10: 45027 | U10: Single | V10: Female | W10: =DATEDIF(Q10,TODAY(),"Y") -> 44 | X10: =IF(ABS(Table1[[#This Row],[AGE]])>59,"60 and above",IF(ABS(Table1[[#This Row],[AGE]])>49,"50-59",IF(ABS(Table1[[#This Row],[AGE]])>39,"40-49",IF(ABS(Table1[[#This Row],[AGE]])>29,"30-39",IF(ABS(Table1[[#This Row],[AGE]])>19,"20-29",""))))) -> 40-49 | Y10: Metro Manila | Z10: Phase 9B Block 3B Lot 11 Daphne St., Greenwoods Village | AA10: Sampaloc 3 | AB10: Dasmariñas City | AC10: Cavite | AD10: 4114 | AE10: Doctor of Medicine | AF10: Medicine | AG10: RA 1080 | AH10: 0110816 | AI10: 45769 | AJ10: 2004285297 | AK10: 1210-1267-7170 | AL10: 0800-0097-7369 | AM10: 254-450-036 | AN10: 0917-584-4880 | AO10: N/A | AP10: bethzaidafabian@gmail.com
A11: 10 | B11: OSEC-DOHB-MDSPT3-270002-2022 | C11: Medical Specialist III (Part-time) (Neurologist) | D11: Neurologist | E11: Medical Specialist III | F11: Internal Medicine Department | G11: Physician | H11: Medical Division | I11: 24 | J11: =LOOKUP(Table1[[#This Row],[SALARY GRADE]],{1,2,3,4,5,6,7,8,9,10,11,12,13,14,15,16,17,18,19,20,21,22,23,24,25,26,27,28,29,30,31,32,33},{14364,15522,16486,17506,18581,19716,20914,22423,24329,26917,31705,33947,36125,38764,42178,45694,49562,53818,59153,66052,73303,81796,91306,102603,116643,131807,148940,167129,187531,210718,300961,356237,449157}) -> 102603 | K11: 2nd | L11: =IF(Table1[[#This Row],[LAST]]="","Unfilled","Filled") -> Filled | M11: Chua | N11: Ronald | O11: Dologuin | Q11: 32406 | R11: 46064 | S11: 46064 | T11: 46064 | U11: Single | V11: Male | W11: =DATEDIF(Q11,TODAY(),"Y") -> 37 | X11: =IF(ABS(Table1[[#This Row],[AGE]])>59,"60 and above",IF(ABS(Table1[[#This Row],[AGE]])>49,"50-59",IF(ABS(Table1[[#This Row],[AGE]])>39,"40-49",IF(ABS(Table1[[#This Row],[AGE]])>29,"30-39",IF(ABS(Table1[[#This Row],[AGE]])>19,"20-29",""))))) -> 30-39 | Y11: Manila | Z11: 1952 Ipil St. | AA11: Sta. Cruz | AB11: Manila City | AC11: Metro Manila | AD11: 1003 | AE11: Doctor of Medicine | AF11: Medicine | AG11: RA 1080 | AH11: 0127321 | AI11: 46285 | AJ11: 2004854373 | AK11: 1211-5943-6377 | AL11: 0102-5429-9567 | AM11: 461-105-367 | AN11: 0917-564-0437 | AO11: 8253-6911 | AP11: ronaldchua@gmail.com
A12: 11 | B12: OSEC-DOHB-MDSPT3-270003-2022 | C12: Medical Specialist III (Part-time) (IDS) | D12: Infectious Disease Specialist | E12: Medical Specialist III | F12: Internal Medicine Department | G12: Physician | H12: Medical Division | I12: 24 | J12: =LOOKUP(Table1[[#This Row],[SALARY GRADE]],{1,2,3,4,5,6,7,8,9,10,11,12,13,14,15,16,17,18,19,20,21,22,23,24,25,26,27,28,29,30,31,32,33},{14364,15522,16486,17506,18581,19716,20914,22423,24329,26917,31705,33947,36125,38764,42178,45694,49562,53818,59153,66052,73303,81796,91306,102603,116643,131807,148940,167129,187531,210718,300961,356237,449157}) -> 102603 | K12: 2nd | L12: =IF(Table1[[#This Row],[LAST]]="","Unfilled","Filled") -> Filled | M12: Mantaring | N12: Dan Meynard | O12: Lagbas | Q12: 33397 | R12: 45126 | S12: 45126 | T12: 45126 | U12: Single | V12: Male | W12: =DATEDIF(Q12,TODAY(),"Y") -> 35 | X12: =IF(ABS(Table1[[#This Row],[AGE]])>59,"60 and above",IF(ABS(Table1[[#This Row],[AGE]])>49,"50-59",IF(ABS(Table1[[#This Row],[AGE]])>39,"40-49",IF(ABS(Table1[[#This Row],[AGE]])>29,"30-39",IF(ABS(Table1[[#This Row],[AGE]])>19,"20-29",""))))) -> 30-39 | Y12: Al Khobar, KSA | Z12: Ph 3 Blk 9 Lot 2, Governor's Hills Subd. | AA12: Biclatan | AB12: General Trias City | AC12: Cavite | AD12: 4107 | AE12: Doctor of Medicine | AF12: Medicine | AG12: RA 1080 | AH12: 0134205 | AI12: 45816 | AJ12: 2006346341 | AK12: 1213-2189-7503 | AL12: 0102-6100-1115 | AM12: 337-134-221 | AN12: 0905-283-4736 | AO12: (046) 402-1617 | AP12: danmeynard.mantaring@gmail.com
A13: 12 | B13: OSEC-DOHB-MDSPT3-270004-2022 | C13: Medical Specialist III (Part-time) (Sonologist) | D13: Sonologist | E13: Medical Specialist III | F13: Obstetrics-Gynecology Department | G13: Physician | H13: Medical Division | I13: 24 | J13: =LOOKUP(Table1[[#This Row],[SALARY GRADE]],{1,2,3,4,5,6,7,8,9,10,11,12,13,14,15,16,17,18,19,20,21,22,23,24,25,26,27,28,29,30,31,32,33},{14364,15522,16486,17506,18581,19716,20914,22423,24329,26917,31705,33947,36125,38764,42178,45694,49562,53818,59153,66052,73303,81796,91306,102603,116643,131807,148940,167129,187531,210718,300961,356237,449157}) -> 102603 | K13: 2nd | L13: =IF(Table1[[#This Row],[LAST]]="","Unfilled","Filled") -> Filled | M13: Marcaida | N13: David | O13: Valdemoro | Q13: 26327 | R13: 45463 | S13: 45463 | T13: 45463 | U13: Single | V13: Male | W13: =DATEDIF(Q13,TODAY(),"Y") -> 54 | X13: =IF(ABS(Table1[[#This Row],[AGE]])>59,"60 and above",IF(ABS(Table1[[#This Row],[AGE]])>49,"50-59",IF(ABS(Table1[[#This Row],[AGE]])>39,"40-49",IF(ABS(Table1[[#This Row],[AGE]])>29,"30-39",IF(ABS(Table1[[#This Row],[AGE]])>19,"20-29",""))))) -> 50-59 | Y13: Aroroy, Masbate | Z13: 13 Carissa, Doña Manuela | AA13: Pamplona Tres | AB13: Las Piñas City | AC13: Metro Manila | AD13: 1740 | AE13: Doctor of Medicine | AF13: Medicine | AG13: RA 1080 | AH13: 090068 | AI13: 46416 | AJ13: 2001754190 | AK13: 1210-6704-2897 | AL13: 0202-5017-8698 | AM13: 205-436-533 | AN13: 0917-860-8090 | AO13: N/A | AP13: periphnymu@gmail.com
A14: 13 | B14: OSEC-DOHB-MDSPT3-270005-2021 | C14: Medical Specialist III (Part-time) (Pulmonolgist) | D14: Pulmonologist | E14: Medical Specialist III | F14: Internal Medicine Department | G14: Physician | H14: Medical Division | I14: 24 | J14: =LOOKUP(Table1[[#This Row],[SALARY GRADE]],{1,2,3,4,5,6,7,8,9,10,11,12,13,14,15,16,17,18,19,20,21,22,23,24,25,26,27,28,29,30,31,32,33},{14364,15522,16486,17506,18581,19716,20914,22423,24329,26917,31705,33947,36125,38764,42178,45694,49562,53818,59153,66052,73303,81796,91306,102603,116643,131807,148940,167129,187531,210718,300961,356237,449157}) -> 102603 | K14: 2nd | L14: =IF(Table1[[#This Row],[LAST]]="","Unfilled","Filled") -> Filled | M14: Estrella | N14: Noel | O14: Valdepeña | Q14: 27394 | R14: 45019 | S14: 45019 | T14: 45019 | U14: Single | V14: Male | W14: =DATEDIF(Q14,TODAY(),"Y") -> 51 | X14: =IF(ABS(Table1[[#This Row],[AGE]])>59,"60 and above",IF(ABS(Table1[[#This Row],[AGE]])>49,"50-59",IF(ABS(Table1[[#This Row],[AGE]])>39,"40-49",IF(ABS(Table1[[#This Row],[AGE]])>29,"30-39",IF(ABS(Table1[[#This Row],[AGE]])>19,"20-29",""))))) -> 50-59 | Y14: Torrijos, Marinduque | Z14: B17 L27-E Basilio Estanislao St., BF Resort Village | AA14: Talon Dos | AB14: Las Piñas City | AC14: Metro Manila | AD14: 1740 | AE14: Doctor of Medicine | AF14: Medicine | AG14: RA 1080 | AH14: 0094493 | AI14: 46022 | AJ14: 2006306691 | AK14: 0141-3003-5607 | AL14: 0802-5092-5925 | AM14: 217-710-251 | AN14: 0917-890-3195 | AO14: (02) 8874-8558 | AP14: noelestrella_md@yahoo.com
A15: 14 | B15: OSEC-DOHB-MDSPT3-270006-2021 | C15: Medical Specialist III (Part-time) (Cardiologist) | D15: Cardiologist | E15: Medical Specialist III | F15: Internal Medicine Department | G15: Physician | H15: Medical Division | I15: 24 | J15: =LOOKUP(Table1[[#This Row],[SALARY GRADE]],{1,2,3,4,5,6,7,8,9,10,11,12,13,14,15,16,17,18,19,20,21,22,23,24,25,26,27,28,29,30,31,32,33},{14364,15522,16486,17506,18581,19716,20914,22423,24329,26917,31705,33947,36125,38764,42178,45694,49562,53818,59153,66052,73303,81796,91306,102603,116643,131807,148940,167129,187531,210718,300961,356237,449157}) -> 102603 | K15: 2nd | L15: =IF(Table1[[#This Row],[LAST]]="","Unfilled","Filled") -> Filled | M15: Gutierrez | N15: Ian Lordeo | O15: Arcusa | Q15: 32550 | R15: 44691 | S15: 44691 | T15: 44691 | U15: Married | V15: Male | W15: =DATEDIF(Q15,TODAY(),"Y") -> 37 | X15: =IF(ABS(Table1[[#This Row],[AGE]])>59,"60 and above",IF(ABS(Table1[[#This Row],[AGE]])>49,"50-59",IF(ABS(Table1[[#This Row],[AGE]])>39,"40-49",IF(ABS(Table1[[#This Row],[AGE]])>29,"30-39",IF(ABS(Table1[[#This Row],[AGE]])>19,"20-29",""))))) -> 30-39 | Y15: Rosario, Cavite | Z15: 258 Duhat Rd., Justinville | AA15: Panapaan VII | AB15: Bacoor City | AC15: Cavite | AD15: 4102 | AE15: Doctor of Medicine | AF15: Medicine | AG15: RA 1080 | AH15: 0127426 | AI15: 46064 | AJ15: 2006083593 | AK15: 1213-0111-2094 | AL15: 0802-5830-8216 | AM15: 283-613-262 | AN15: 0917-529-9182 | AO15: 471-0557 | AP15: ian_lordeo_gutierrez@yahoo.com
A16: 15 | B16: OSEC-DOHB-MDSPT3-270007-2021 | C16: Medical Specialist III (Part-time) (Nephrologist) | D16: Nephrologist | E16: Medical Specialist III | F16: Internal Medicine Department | G16: Physician | H16: Medical Division | I16: 24 | J16: =LOOKUP(Table1[[#This Row],[SALARY GRADE]],{1,2,3,4,5,6,7,8,9,10,11,12,13,14,15,16,17,18,19,20,21,22,23,24,25,26,27,28,29,30,31,32,33},{14364,15522,16486,17506,18581,19716,20914,22423,24329,26917,31705,33947,36125,38764,42178,45694,49562,53818,59153,66052,73303,81796,91306,102603,116643,131807,148940,167129,187531,210718,300961,356237,449157}) -> 102603 | K16: 2nd | L16: =IF(Table1[[#This Row],[LAST]]="","Unfilled","Filled") -> Filled | M16: Garibay | N16: Mavis Athina | O16: Abuel | Q16: 32376 | R16: 44748 | S16: 44748 | T16: 44748 | U16: Single | V16: Female | W16: =DATEDIF(Q16,TODAY(),"Y") -> 37 | X16: =IF(ABS(Table1[[#This Row],[AGE]])>59,"60 and above",IF(ABS(Table1[[#This Row],[AGE]])>49,"50-59",IF(ABS(Table1[[#This Row],[AGE]])>39,"40-49",IF(ABS(Table1[[#This Row],[AGE]])>29,"30-39",IF(ABS(Table1[[#This Row],[AGE]])>19,"20-29",""))))) -> 30-39 | Y16: Angono, Rizal | Z16: Blk 4 Lot 6 Jade St. MS5 Village Lancaster | AA16: Navarro | AB16: General Trias City | AC16: Cavite | AD16: 4107 | AE16: Doctor of Medicine | AF16: Medicine | AG16: RA 1080 | AH16: 0127874 | AI16: 46255 | AJ16: 2004875794 | AK16: 1211-6739-8577 | AL16: 0302-5829-0441 | AM16: 469-230-086 | AN16: 0917-136-5399 | AO16: N/A | AP16: mavisgaribay@yahoo.com
A17: 16 | B17: OSEC-DOHB-MDSPT3-270008-2021 | C17: Medical Specialist III (Part-time) (Neonatologist) | D17: Neonatologist | E17: Medical Specialist III | F17: Pediatrics Department | G17: Physician | H17: Medical Division | I17: 24 | J17: =LOOKUP(Table1[[#This Row],[SALARY GRADE]],{1,2,3,4,5,6,7,8,9,10,11,12,13,14,15,16,17,18,19,20,21,22,23,24,25,26,27,28,29,30,31,32,33},{14364,15522,16486,17506,18581,19716,20914,22423,24329,26917,31705,33947,36125,38764,42178,45694,49562,53818,59153,66052,73303,81796,91306,102603,116643,131807,148940,167129,187531,210718,300961,356237,449157}) -> 102603 | K17: 2nd | L17: =IF(Table1[[#This Row],[LAST]]="","Unfilled","Filled") -> Filled | M17: Vicarez-Palogan | N17: Chelsea | O17: Gonzales | Q17: 32082 | R17: 44691 | S17: 44691 | T17: 44691 | U17: Married | V17: Female | W17: =DATEDIF(Q17,TODAY(),"Y") -> 38 | X17: =IF(ABS(Table1[[#This Row],[AGE]])>59,"60 and above",IF(ABS(Table1[[#This Row],[AGE]])>49,"50-59",IF(ABS(Table1[[#This Row],[AGE]])>39,"40-49",IF(ABS(Table1[[#This Row],[AGE]])>29,"30-39",IF(ABS(Table1[[#This Row],[AGE]])>19,"20-29",""))))) -> 30-39 | Y17: Manila | Z17: 26 Evangeline Reyes BF Resort | AA17: Talon Dos | AB17: Las Piñas City | AC17: NCR | AD17: 1747 | AE17: Doctor of Medicine | AF17: Medicine | AG17: RA 1080 | AH17: 0126199 | AI17: 46033 | AJ17: 2005217481 | AK17: 1212-02238-6406 | AL17: 0105-0495-3055 | AM17: 305-897-411 | AN17: 0917-536-2901 | AO17: N/A | AP17: chelseavicarez@yahoo.com
A18: 17 | B18: OSEC-DOHB-MDSP3-270023-2020 | C18: Medical Specialist III (Obstetrician) | D18: Obstetrician | E18: Medical Specialist III | F18: Obstetrics-Gynecology Department | G18: Physician | H18: Medical Division | I18: 24 | J18: =LOOKUP(Table1[[#This Row],[SALARY GRADE]],{1,2,3,4,5,6,7,8,9,10,11,12,13,14,15,16,17,18,19,20,21,22,23,24,25,26,27,28,29,30,31,32,33},{14364,15522,16486,17506,18581,19716,20914,22423,24329,26917,31705,33947,36125,38764,42178,45694,49562,53818,59153,66052,73303,81796,91306,102603,116643,131807,148940,167129,187531,210718,300961,356237,449157}) -> 102603 | K18: 2nd | L18: =IF(Table1[[#This Row],[LAST]]="","Unfilled","Filled") -> Filled | M18: Ibañez | N18: Maria Girlie | O18: Jeresano | Q18: 24976 | R18: 42353 | S18: 44743 | T18: 45566 | U18: Married | V18: Female | W18: =DATEDIF(Q18,TODAY(),"Y") -> 58 | X18: =IF(ABS(Table1[[#This Row],[AGE]])>59,"60 and above",IF(ABS(Table1[[#This Row],[AGE]])>49,"50-59",IF(ABS(Table1[[#This Row],[AGE]])>39,"40-49",IF(ABS(Table1[[#This Row],[AGE]])>29,"30-39",IF(ABS(Table1[[#This Row],[AGE]])>19,"20-29",""))))) -> 50-59 | Y18: Gubat, Sorsogon | Z18: #6 (Block 7 Lot 24) San Pablo St., Pacita Complex 1 | AA18: Pacita 1 | AB18: San Pedro | AC18: Laguna | AD18: 4023 | AE18: Doctor of Medicine | AF18: Medicine | AG18: RA 1080 | AH18: 0085063 | AI18: 45795 | AJ18: 2004815670 | AK18: 1210-9536-3456 | AL18: 1904-8000-3652 | AM18: 283-378-620 | AN18: 0917-890-8767 | AO18: N/A | AP18: betangirl@yahoo.com
A19: 18 | B19: OSEC-DOHB-DENT4-270035-2022 | C19: Dentist IV | E19: Dentist IV | F19: Dental Department | G19: Dentist | H19: Medical Division | I19: 23 | J19: =LOOKUP(Table1[[#This Row],[SALARY GRADE]],{1,2,3,4,5,6,7,8,9,10,11,12,13,14,15,16,17,18,19,20,21,22,23,24,25,26,27,28,29,30,31,32,33},{14364,15522,16486,17506,18581,19716,20914,22423,24329,26917,31705,33947,36125,38764,42178,45694,49562,53818,59153,66052,73303,81796,91306,102603,116643,131807,148940,167129,187531,210718,300961,356237,449157}) -> 91306 | K19: 2nd | L19: =IF(Table1[[#This Row],[LAST]]="","Unfilled","Filled") -> Filled | M19: Rivera | N19: Marilou | O19: Fajardo | Q19: 23998 | R19: 37280 | S19: 44363 | T19: 45687 | U19: Married | V19: Female | W19: =DATEDIF(Q19,TODAY(),"Y") -> 60 | X19: =IF(ABS(Table1[[#This Row],[AGE]])>59,"60 and above",IF(ABS(Table1[[#This Row],[AGE]])>49,"50-59",IF(ABS(Table1[[#This Row],[AGE]])>39,"40-49",IF(ABS(Table1[[#This Row],[AGE]])>29,"30-39",IF(ABS(Table1[[#This Row],[AGE]])>19,"20-29",""))))) -> 60 and above | Y19: Alfonso, Cavite | Z19: 4 Rizal | AA19: III | AB19: Alfonso | AC19: Cavite | AD19: 1742 | AE19: Doctor of Dental Medicine | AF19: Dentistry | AG19: RA 1080 | AH19: 0029093 | AI19: 45913 | AJ19: 2001243333 | AK19: 1030-0008-0261 | AL19: 0802-5016-6617 | AM19: 134-549-420 | AN19: 0917-551-1365 | AO19: N/A | AP19: malufajardorivera@yahoo.com.ph
A20: 19 | B20: OSEC-DOHB-MDOF4-270012-2022 | C20: Medical Officer IV | D20: Anesthesiologist | E20: Medical Officer IV | F20: Anesthesiology Department | G20: Physician | H20: Medical Division | I20: 23 | J20: =LOOKUP(Table1[[#This Row],[SALARY GRADE]],{1,2,3,4,5,6,7,8,9,10,11,12,13,14,15,16,17,18,19,20,21,22,23,24,25,26,27,28,29,30,31,32,33},{14364,15522,16486,17506,18581,19716,20914,22423,24329,26917,31705,33947,36125,38764,42178,45694,49562,53818,59153,66052,73303,81796,91306,102603,116643,131807,148940,167129,187531,210718,300961,356237,449157}) -> 91306 | K20: 2nd | L20: =IF(Table1[[#This Row],[LAST]]="","Unfilled","Filled") -> Filled | M20: Lope | N20: Diana Jane | O20: Casugod | Q20: 31747 | R20: 44851 | S20: 44851 | T20: 44851 | U20: Single | V20: Female | W20: =DATEDIF(Q20,TODAY(),"Y") -> 39 | X20: =IF(ABS(Table1[[#This Row],[AGE]])>59,"60 and above",IF(ABS(Table1[[#This Row],[AGE]])>49,"50-59",IF(ABS(Table1[[#This Row],[AGE]])>39,"40-49",IF(ABS(Table1[[#This Row],[AGE]])>29,"30-39",IF(ABS(Table1[[#This Row],[AGE]])>19,"20-29",""))))) -> 30-39 | Y20: Manila | Z20: No. 189 Doña Alicia Subd. | AA20: Ligas I | AB20: Bacoor City | AC20: Cavite | AD20: 4102 | AE20: Doctor of Medicine | AF20: Medicine | AG20: RA 1080 | AH20: 0128043 | AI20: 46034 | AJ20: 2005345316 | AK20: 1212-1991-3690 | AL20: 0802-5423-0859 | AM20: 319-784-022 | AN20: 0977-835-2006 | AO20: N/A | AP20: dianajane.lope@gmail.com
A21: 20 | B21: OSEC-DOHB-MDOF4-270018-2020 | C21: Medical Officer IV | D21: Pediatrician | E21: Medical Officer IV | F21: Pediatrics Department | G21: Physician | H21: Medical Division | I21: 23 | J21: =LOOKUP(Table1[[#This Row],[SALARY GRADE]],{1,2,3,4,5,6,7,8,9,10,11,12,13,14,15,16,17,18,19,20,21,22,23,24,25,26,27,28,29,30,31,32,33},{14364,15522,16486,17506,18581,19716,20914,22423,24329,26917,31705,33947,36125,38764,42178,45694,49562,53818,59153,66052,73303,81796,91306,102603,116643,131807,148940,167129,187531,210718,300961,356237,449157}) -> 91306 | K21: 2nd | L21: =IF(Table1[[#This Row],[LAST]]="","Unfilled","Filled") -> Filled | M21: Bañaga | N21: Mara Joanna | O21: Palarca | Q21: 32602 | R21: 46092 | S21: 46092 | T21: 46092 | U21: Single | V21: Female | W21: =DATEDIF(Q21,TODAY(),"Y") -> 37 | X21: =IF(ABS(Table1[[#This Row],[AGE]])>59,"60 and above",IF(ABS(Table1[[#This Row],[AGE]])>49,"50-59",IF(ABS(Table1[[#This Row],[AGE]])>39,"40-49",IF(ABS(Table1[[#This Row],[AGE]])>29,"30-39",IF(ABS(Table1[[#This Row],[AGE]])>19,"20-29",""))))) -> 30-39 | Y21: Manila | Z21: #1 Tickling St., Novaville Subd. | AA21: 170 | AB21: Caloocan City | AC21: Metro Manila | AD21: 1400 | AE21: Doctor of Medicine | AF21: Medicine | AG21: RA 1080 | AH21: 0139666 | AI21: 46116 | AJ21: 2005539158 | AK21: 1212-4256-1527 | AL21: 0302-6266-2566 | AM21: 353-614-057 | AN21: 0998-317-512 | AO21: N/A | AP21: mara.banaga@gmail.com
A22: 21 | B22: OSEC-DOHB-MDOF4-270019-2020 | C22: Medical Officer IV | D22: General Practitioner | E22: Medical Officer IV | F22: Office of the Chief of Allied Health Professional | G22: Physician | H22: Medical Division | I22: 23 | J22: =LOOKUP(Table1[[#This Row],[SALARY GRADE]],{1,2,3,4,5,6,7,8,9,10,11,12,13,14,15,16,17,18,19,20,21,22,23,24,25,26,27,28,29,30,31,32,33},{14364,15522,16486,17506,18581,19716,20914,22423,24329,26917,31705,33947,36125,38764,42178,45694,49562,53818,59153,66052,73303,81796,91306,102603,116643,131807,148940,167129,187531,210718,300961,356237,449157}) -> 91306 | K22: 2nd | L22: =IF(Table1[[#This Row],[LAST]]="","Unfilled","Filled") -> Filled | M22: Gabuten | N22: Ana Maria Elena | O22: Quiros | Q22: 26768 | R22: 38257 | S22: 44383 | T22: 44383 | U22: Single | V22: Female | W22: =DATEDIF(Q22,TODAY(),"Y") -> 53 | X22: =IF(ABS(Table1[[#This Row],[AGE]])>59,"60 and above",IF(ABS(Table1[[#This Row],[AGE]])>49,"50-59",IF(ABS(Table1[[#This Row],[AGE]])>39,"40-49",IF(ABS(Table1[[#This Row],[AGE]])>29,"30-39",IF(ABS(Table1[[#This Row],[AGE]])>19,"20-29",""))))) -> 50-59 | Y22: Pasay City | Z22: 12 Camia St., De Castro Subd. | AA22: Sta. Lucia | AB22: Pasig City | AC22: NCR | AD22: 1600 | AE22: Doctor of Medicine | AF22: Medicine | AG22: RA 1080 | AH22: 0097502 | AI22: 46126 | AJ22: 2001397754 | AK22: 1030-0009-5145 | AL22: 0800-0064-8098 | AM22: 225-249-606 | AN22: 0915-254-7744 | AO22: (02) 788-1720 | AP22: amegabu10@yahoo.com
A23: 22 | B23: OSEC-DOHB-MDOF4-270020-2020 | C23: Medical Officer IV | D23: Surgeon | E23: Medical Officer IV | F23: Surgery Department | G23: Physician | H23: Medical Division | I23: 23 | J23: =LOOKUP(Table1[[#This Row],[SALARY GRADE]],{1,2,3,4,5,6,7,8,9,10,11,12,13,14,15,16,17,18,19,20,21,22,23,24,25,26,27,28,29,30,31,32,33},{14364,15522,16486,17506,18581,19716,20914,22423,24329,26917,31705,33947,36125,38764,42178,45694,49562,53818,59153,66052,73303,81796,91306,102603,116643,131807,148940,167129,187531,210718,300961,356237,449157}) -> 91306 | K23: 2nd | L23: =IF(Table1[[#This Row],[LAST]]="","Unfilled","Filled") -> Filled | M23: Mendoza | N23: Hazel | O23: Alarcon | Q23: 32833 | R23: 44960 | S23: 44960 | T23: 44960 | U23: Single | V23: Female | W23: =DATEDIF(Q23,TODAY(),"Y") -> 36 | X23: =IF(ABS(Table1[[#This Row],[AGE]])>59,"60 and above",IF(ABS(Table1[[#This Row],[AGE]])>49,"50-59",IF(ABS(Table1[[#This Row],[AGE]])>39,"40-49",IF(ABS(Table1[[#This Row],[AGE]])>29,"30-39",IF(ABS(Table1[[#This Row],[AGE]])>19,"20-29",""))))) -> 30-39 | Y23: Quezon City | Z23: 150 Proverb Vina Village | AA23: Poblacion IV-D | AB23: Imus City | AC23: Cavite | AD23: 4103 | AE23: Doctor of Medicine | AF23: Medicine | AG23: RA 1080 | AH23: 0128427 | AI23: 46712 | AJ23: 2004703711 | AK23: 1211-8041-3237 | AL23: 2100-0019-7542 | AM23: 462-469-085 | AN23: 0917-829-2594 | AO23: N/A | AP23: dochazelmendoza@gmail.com
A24: 23 | B24: OSEC-DOHB-MDOF4-270021-2020 | C24: Medical Officer IV | D24: Internist | E24: Medical Officer IV | F24: Internal Medicine Department | G24: Physician | H24: Medical Division | I24: 23 | J24: =LOOKUP(Table1[[#This Row],[SALARY GRADE]],{1,2,3,4,5,6,7,8,9,10,11,12,13,14,15,16,17,18,19,20,21,22,23,24,25,26,27,28,29,30,31,32,33},{14364,15522,16486,17506,18581,19716,20914,22423,24329,26917,31705,33947,36125,38764,42178,45694,49562,53818,59153,66052,73303,81796,91306,102603,116643,131807,148940,167129,187531,210718,300961,356237,449157}) -> 91306 | K24: 2nd | L24: =IF(Table1[[#This Row],[LAST]]="","Unfilled","Filled") -> Filled | M24: Pereyra-Borlongan | N24: Maria Yña Eluisia | O24: Tomagan | Q24: 32091 | R24: 45019 | S24: 45019 | T24: 45474 | U24: Married | V24: Female | W24: =DATEDIF(Q24,TODAY(),"Y") -> 38 | X24: =IF(ABS(Table1[[#This Row],[AGE]])>59,"60 and above",IF(ABS(Table1[[#This Row],[AGE]])>49,"50-59",IF(ABS(Table1[[#This Row],[AGE]])>39,"40-49",IF(ABS(Table1[[#This Row],[AGE]])>29,"30-39",IF(ABS(Table1[[#This Row],[AGE]])>19,"20-29",""))))) -> 30-39 | Y24: Manila | Z24: Unit 1215 Astra Bldg., Pasig Blvd., Prisma Residences | AA24: Bagong Ilog | AB24: Pasig City | AC24: Metro Manila | AD24: 1600 | AE24: Doctor of Medicine | AF24: Medicine | AG24: RA 1080 | AH24: 0129486 | AI24: 46671 | AJ24: 2005559346 | AK24: 1211-6083-4915 | AL24: 0102-5429-9338 | AM24: 319-221-335 | AN24: 0968-854-6080 | AO24: N/A | AP24: ynapereyra@gmail.com
A25: 24 | B25: OSEC-DOHB-MDOF4-270022-2020 | C25: Medical Officer IV | D25: Emergency Med | E25: Medical Officer IV | F25: Emergency Medicine Department | G25: Physician | H25: Medical Division | I25: 23 | J25: =LOOKUP(Table1[[#This Row],[SALARY GRADE]],{1,2,3,4,5,6,7,8,9,10,11,12,13,14,15,16,17,18,19,20,21,22,23,24,25,26,27,28,29,30,31,32,33},{14364,15522,16486,17506,18581,19716,20914,22423,24329,26917,31705,33947,36125,38764,42178,45694,49562,53818,59153,66052,73303,81796,91306,102603,116643,131807,148940,167129,187531,210718,300961,356237,449157}) -> 91306 | K25: 2nd | L25: =IF(Table1[[#This Row],[LAST]]="","Unfilled","Filled") -> Filled | M25: Sarrosa | N25: Noel Angelo | O25: Solidor | Q25: 35362 | R25: 45540 | S25: 45540 | T25: 45540 | U25: Single | V25: Male | W25: =DATEDIF(Q25,TODAY(),"Y") -> 29 | X25: =IF(ABS(Table1[[#This Row],[AGE]])>59,"60 and above",IF(ABS(Table1[[#This Row],[AGE]])>49,"50-59",IF(ABS(Table1[[#This Row],[AGE]])>39,"40-49",IF(ABS(Table1[[#This Row],[AGE]])>29,"30-39",IF(ABS(Table1[[#This Row],[AGE]])>19,"20-29",""))))) -> 20-29 | Y25: Makati City | Z25: Block 70 Lot 6 Criselda Cecilio St., Classic I, BF Resort Village | AA25: Talon Dos | AB25: Las Piñas City | AC25: NCR | AD25: 1747 | AE25: Doctor of Medicine | AF25: Medicine | AG25: RA 1080 | AH25: 0150829 | AI25: 46319 | AJ25: 2005870559 | AK25: 1212-7664-7248 | AL25: 0125-0135-9457 | AM25: 501-164-235 | AN25: 0917-712-8054 | AO25: (02) 8873-4561 | AP25: noelsarrosa@gmail.com
A26: 25 | B26: OSEC-DOHB-MDSP2-270010-2022 | C26: Medical Specialist II (Internist) | D26: Internist | E26: Medical Specialist II | F26: Internal Medicine Department | G26: Physician | H26: Medical Division | I26: 23 | J26: =LOOKUP(Table1[[#This Row],[SALARY GRADE]],{1,2,3,4,5,6,7,8,9,10,11,12,13,14,15,16,17,18,19,20,21,22,23,24,25,26,27,28,29,30,31,32,33},{14364,15522,16486,17506,18581,19716,20914,22423,24329,26917,31705,33947,36125,38764,42178,45694,49562,53818,59153,66052,73303,81796,91306,102603,116643,131807,148940,167129,187531,210718,300961,356237,449157}) -> 91306 | K26: 2nd | L26: =IF(Table1[[#This Row],[LAST]]="","Unfilled","Filled") -> Filled | M26: Berenguer | N26: Joe Vincent | O26: Villa | Q26: 32099 | R26: 44363 | S26: 44363 | T26: 45306 | U26: Married | V26: Male | W26: =DATEDIF(Q26,TODAY(),"Y") -> 38 | X26: =IF(ABS(Table1[[#This Row],[AGE]])>59,"60 and above",IF(ABS(Table1[[#This Row],[AGE]])>49,"50-59",IF(ABS(Table1[[#This Row],[AGE]])>39,"40-49",IF(ABS(Table1[[#This Row],[AGE]])>29,"30-39",IF(ABS(Table1[[#This Row],[AGE]])>19,"20-29",""))))) -> 30-39 | Y26: Tacloban City, Leyte | Z26: B1 L7 Miller St., Southville Settings Nuvali | AA26: Canlubang | AB26: Calamba City | AC26: Laguna | AD26: 4028 | AE26: Doctor of Medicine | AF26: Medicine | AG26: RA 1080 | AH26: 0127917 | AI26: 46344 | AJ26: 2004652332 | AK26: 1211-3691-3428 | AL26: 0300-0276-6864 | AM26: 270-794-389 | AN26: 0917-117-6574 | AO26: N/A | AP26: joevincentberenguer@gmail.com
A27: 26 | B27: OSEC-DOHB-MDSP2-270011-2022 | C27: Medical Specialist II (Anesthesiologist) | D27: Anesthesiologist | E27: Medical Specialist II | F27: Anesthesiology Department | G27: Physician | H27: Medical Division | I27: 23 | J27: =LOOKUP(Table1[[#This Row],[SALARY GRADE]],{1,2,3,4,5,6,7,8,9,10,11,12,13,14,15,16,17,18,19,20,21,22,23,24,25,26,27,28,29,30,31,32,33},{14364,15522,16486,17506,18581,19716,20914,22423,24329,26917,31705,33947,36125,38764,42178,45694,49562,53818,59153,66052,73303,81796,91306,102603,116643,131807,148940,167129,187531,210718,300961,356237,449157}) -> 91306 | K27: 2nd | L27: =IF(Table1[[#This Row],[LAST]]="","Unfilled","Filled") -> Filled | M27: Garcia | N27: Yves Kristine | O27: Ginete | Q27: 33216 | R27: 45604 | S27: 45604 | T27: 45604 | U27: Single | V27: Female | W27: =DATEDIF(Q27,TODAY(),"Y") -> 35 | X27: =IF(ABS(Table1[[#This Row],[AGE]])>59,"60 and above",IF(ABS(Table1[[#This Row],[AGE]])>49,"50-59",IF(ABS(Table1[[#This Row],[AGE]])>39,"40-49",IF(ABS(Table1[[#This Row],[AGE]])>29,"30-39",IF(ABS(Table1[[#This Row],[AGE]])>19,"20-29",""))))) -> 30-39 | Y27: Quezon City | Z27: 3218 Manila Residence Bocobo, 1160, Jorge Bocobo St., Ermita | AA27: Brgy. 670 | AB27: Manila City | AC27: Metro Manila | AD27: 1000 | AE27: Doctor of Medicine | AF27: Medicine | AG27: RA 1080 | AH27: 0137208 | AI27: 46365 | AJ27: 2005577217 | AK27: 1212-4017-2424 | AL27: 0102-5746-7274 | AM27: 709-686-643 | AN27: 0926-740-0820 | AO27: N/A | AP27: yvesgarcia@gmail.com
A28: 27 | B28: OSEC-DOHB-MDSP2-270012-2020 | C28: Medical Specialist II (Radiologist) | D28: Radiologist | E28: Medical Specialist II | F28: Radiology Department | G28: Physician | H28: Medical Division | I28: 23 | J28: =LOOKUP(Table1[[#This Row],[SALARY GRADE]],{1,2,3,4,5,6,7,8,9,10,11,12,13,14,15,16,17,18,19,20,21,22,23,24,25,26,27,28,29,30,31,32,33},{14364,15522,16486,17506,18581,19716,20914,22423,24329,26917,31705,33947,36125,38764,42178,45694,49562,53818,59153,66052,73303,81796,91306,102603,116643,131807,148940,167129,187531,210718,300961,356237,449157}) -> 91306 | K28: 2nd | L28: =IF(Table1[[#This Row],[LAST]]="","Unfilled","Filled") -> Filled | M28: Gacutan | N28: Rico | O28: Vasquez | Q28: 26762 | R28: 42618 | S28: 44424 | T28: 44424 | U28: Married | V28: Male | W28: =DATEDIF(Q28,TODAY(),"Y") -> 53 | X28: =IF(ABS(Table1[[#This Row],[AGE]])>59,"60 and above",IF(ABS(Table1[[#This Row],[AGE]])>49,"50-59",IF(ABS(Table1[[#This Row],[AGE]])>39,"40-49",IF(ABS(Table1[[#This Row],[AGE]])>29,"30-39",IF(ABS(Table1[[#This Row],[AGE]])>19,"20-29",""))))) -> 50-59 | Y28: Balanga City, Bataan | Z28: B8 L10 Rainforest St., Sunnycrest Village | AA28: Salitran II | AB28: Dasmariñas City | AC28: Cavite | AD28: 4114 | AE28: Doctor of Medicine | AF28: Medicine | AG28: RA 1080 | AH28: 0091411 | AI28: 46120 | AJ28: 2001121167 | AK28: 0031-0619-9701 | AL28: 0300-0200-9761 | AM28: 204-658-622 | AN28: 0920-927-4763 | AO28: N/A | AP28: coricsmd@yahoo.com
A29: 28 | B29: OSEC-DOHB-MDSP2-270012-2022 | C29: Medical Specialist II (Surgeon) | D29: Surgeon | E29: Medical Specialist II | F29: Surgery Department | G29: Physician | H29: Medical Division | I29: 23 | J29: =LOOKUP(Table1[[#This Row],[SALARY GRADE]],{1,2,3,4,5,6,7,8,9,10,11,12,13,14,15,16,17,18,19,20,21,22,23,24,25,26,27,28,29,30,31,32,33},{14364,15522,16486,17506,18581,19716,20914,22423,24329,26917,31705,33947,36125,38764,42178,45694,49562,53818,59153,66052,73303,81796,91306,102603,116643,131807,148940,167129,187531,210718,300961,356237,449157}) -> 91306 | K29: 2nd | L29: =IF(Table1[[#This Row],[LAST]]="","Unfilled","Filled") -> Filled | M29: Balmores | N29: Bob | O29: Caranico | Q29: 32279 | R29: 45083 | S29: 45083 | T29: 45083 | U29: Married | V29: Male | W29: =DATEDIF(Q29,TODAY(),"Y") -> 38 | X29: =IF(ABS(Table1[[#This Row],[AGE]])>59,"60 and above",IF(ABS(Table1[[#This Row],[AGE]])>49,"50-59",IF(ABS(Table1[[#This Row],[AGE]])>39,"40-49",IF(ABS(Table1[[#This Row],[AGE]])>29,"30-39",IF(ABS(Table1[[#This Row],[AGE]])>19,"20-29",""))))) -> 30-39 | Y29: General Santos City | Z29: 24 Maganda JS Ville | AA29: Dulong Bayan | AB29: Bacoor City | AC29: Cavite | AD29: 4102 | AE29: Doctor of Medicine | AF29: Medicine | AG29: RA 1080 | AH29: 0127248 | AI29: 45793 | AJ29: 2006333495 | AK29: 1212-7075-6275 | AL29: 0202-5113-4597 | AM29: 251-101-824 | AN29: 0945-677-7061 | AO29: (046) 434-4680 | AP29: bcbalmores14@gmail.com
A30: 29 | B30: OSEC-DOHB-MDSP2-270013-2020 | C30: Medical Specialist II (Pediatrician) | D30: Pediatrician | E30: Medical Specialist II | F30: Pediatrics Department | G30: Physician | H30: Medical Division | I30: 23 | J30: =LOOKUP(Table1[[#This Row],[SALARY GRADE]],{1,2,3,4,5,6,7,8,9,10,11,12,13,14,15,16,17,18,19,20,21,22,23,24,25,26,27,28,29,30,31,32,33},{14364,15522,16486,17506,18581,19716,20914,22423,24329,26917,31705,33947,36125,38764,42178,45694,49562,53818,59153,66052,73303,81796,91306,102603,116643,131807,148940,167129,187531,210718,300961,356237,449157}) -> 91306 | K30: 2nd | L30: =IF(Table1[[#This Row],[LAST]]="","Unfilled","Filled") -> Filled | M30: Alfonso-Tebelin | N30: Roda | O30: Alfonso | Q30: 29831 | R30: 42401 | S30: 44383 | T30: 44383 | U30: Married | V30: Female | W30: =DATEDIF(Q30,TODAY(),"Y") -> 44 | X30: =IF(ABS(Table1[[#This Row],[AGE]])>59,"60 and above",IF(ABS(Table1[[#This Row],[AGE]])>49,"50-59",IF(ABS(Table1[[#This Row],[AGE]])>39,"40-49",IF(ABS(Table1[[#This Row],[AGE]])>29,"30-39",IF(ABS(Table1[[#This Row],[AGE]])>19,"20-29",""))))) -> 40-49 | Y30: Cavite City | Z30: 774 Crescini Ext., San Antonio | AA30: 49-M | AB30: Cavite City | AC30: Cavite | AD30: 4100 | AE30: Doctor of Medicine | AF30: Medicine | AG30: RA 1080 | AH30: 0111056 | AI30: 45902 | AJ30: 2004867482 | AK30: 1211-0250-0561 | AL30: 0802-5247-5870 | AM30: 221-602-851 | AN30: 0997-761-8145 | AO30: (046) 851-5258 | AP30: hapiroda@gmail.com
A31: 30 | B31: OSEC-DOHB-MDSP2-270013-2022 | C31: Medical Specialist II (Pathologist) | D31: Pathologist | E31: Medical Specialist II | F31: Obstetrics-Gynecology Department | G31: Physician | H31: Medical Division | I31: 23 | J31: =LOOKUP(Table1[[#This Row],[SALARY GRADE]],{1,2,3,4,5,6,7,8,9,10,11,12,13,14,15,16,17,18,19,20,21,22,23,24,25,26,27,28,29,30,31,32,33},{14364,15522,16486,17506,18581,19716,20914,22423,24329,26917,31705,33947,36125,38764,42178,45694,49562,53818,59153,66052,73303,81796,91306,102603,116643,131807,148940,167129,187531,210718,300961,356237,449157}) -> 91306 | K31: 2nd | L31: =IF(Table1[[#This Row],[LAST]]="","Unfilled","Filled") -> Filled | M31: Blanco | N31: Renzton | O31: Paras | Q31: 33783 | R31: 45523 | S31: 45523 | T31: 45523 | U31: Married | V31: Male | W31: =DATEDIF(Q31,TODAY(),"Y") -> 34 | X31: =IF(ABS(Table1[[#This Row],[AGE]])>59,"60 and above",IF(ABS(Table1[[#This Row],[AGE]])>49,"50-59",IF(ABS(Table1[[#This Row],[AGE]])>39,"40-49",IF(ABS(Table1[[#This Row],[AGE]])>29,"30-39",IF(ABS(Table1[[#This Row],[AGE]])>19,"20-29",""))))) -> 30-39 | Y31: Tanza, Cavite | Z31: 426 Tramo Kanluran St. | AA31: Halayhay | AB31: Tanza | AC31: Cavite | AD31: 4108 | AE31: Doctor of Medicine | AF31: Medicine | AG31: RA 1080 | AH31: 0138567 | AI31: 46201 | AJ31: 2005732172 | AK31: 1212-6440-7292 | AL31: 0825-0846-9949 | AM31: 273-253-736 | AN31: 0939-919-9315 | AO31: (046) 481-8745 | AP31: blancorenzton@gmail.com
A32: 31 | B32: OSEC-DOHB-MDSP2-270014-2022 | C32: Medical Specialist II (Obstretician) | D32: Obstetrician | E32: Medical Specialist II | F32: Obstetrics-Gynecology Department | G32: Physician | H32: Medical Division | I32: 23 | J32: =LOOKUP(Table1[[#This Row],[SALARY GRADE]],{1,2,3,4,5,6,7,8,9,10,11,12,13,14,15,16,17,18,19,20,21,22,23,24,25,26,27,28,29,30,31,32,33},{14364,15522,16486,17506,18581,19716,20914,22423,24329,26917,31705,33947,36125,38764,42178,45694,49562,53818,59153,66052,73303,81796,91306,102603,116643,131807,148940,167129,187531,210718,300961,356237,449157}) -> 91306 | K32: 2nd | L32: =IF(Table1[[#This Row],[LAST]]="","Unfilled","Filled") -> Filled | M32: Ramos-Atanacio | N32: Clarisa | O32: Murillo | Q32: 31539 | R32: 44950 | S32: 44950 | T32: 45301 | U32: Married | V32: Female | W32: =DATEDIF(Q32,TODAY(),"Y") -> 40 | X32: =IF(ABS(Table1[[#This Row],[AGE]])>59,"60 and above",IF(ABS(Table1[[#This Row],[AGE]])>49,"50-59",IF(ABS(Table1[[#This Row],[AGE]])>39,"40-49",IF(ABS(Table1[[#This Row],[AGE]])>29,"30-39",IF(ABS(Table1[[#This Row],[AGE]])>19,"20-29",""))))) -> 40-49 | Y32: Metro Manila | Z32: #16 Jerusalem St. BF Aratiles | AA32: BF Homes | AB32: Parañaque City | AC32: Manila | AD32: 1720 | AE32: Doctor of Medicine | AF32: Medicine | AG32: RA 1080 | AH32: 0134334 | AI32: 45784 | AJ32: 2005157235 | AK32: 1211-8827-1699 | AL32: 0105-0687-7127 | AM32: 275-508-750 | AN32: 0917-584-2686 | AO32: (02) 8644-2757 | AP32: clarisaramos86@gmail.com
A33: 32 | B33: OSEC-DOHB-MDSP2-270014-2020 | C33: Medical Specialist II (Internist) | D33: Internist | E33: Medical Specialist II | F33: Internal Medicine Department | G33: Physician | H33: Medical Division | I33: 23 | J33: =LOOKUP(Table1[[#This Row],[SALARY GRADE]],{1,2,3,4,5,6,7,8,9,10,11,12,13,14,15,16,17,18,19,20,21,22,23,24,25,26,27,28,29,30,31,32,33},{14364,15522,16486,17506,18581,19716,20914,22423,24329,26917,31705,33947,36125,38764,42178,45694,49562,53818,59153,66052,73303,81796,91306,102603,116643,131807,148940,167129,187531,210718,300961,356237,449157}) -> 91306 | K33: 2nd | L33: =IF(Table1[[#This Row],[LAST]]="","Unfilled","Filled") -> Filled | M33: Co | N33: Paul Bernard Bryant | O33: Ng | Q33: 29651 | R33: 44907 | S33: 44907 | T33: 44907 | U33: Married | V33: Male | W33: =DATEDIF(Q33,TODAY(),"Y") -> 45 | X33: =IF(ABS(Table1[[#This Row],[AGE]])>59,"60 and above",IF(ABS(Table1[[#This Row],[AGE]])>49,"50-59",IF(ABS(Table1[[#This Row],[AGE]])>39,"40-49",IF(ABS(Table1[[#This Row],[AGE]])>29,"30-39",IF(ABS(Table1[[#This Row],[AGE]])>19,"20-29",""))))) -> 40-49 | Y33: Manila | Z33: B5 L4 Phase 2, Sunshine Homes | AA33: Francisco de Castro | AB33: GMA | AC33: Cavite | AD33: 4117 | AE33: Doctor of Medicine | AF33: Medicine | AG33: RA 1080 | AH33: 0113425 | AI33: 46544 | AJ33: 2004172400 | AK33: 1211-1373-8037 | AL33: 1202-2255-8330 | AM33: 265-879-165 | AN33: 0969-211-0187 | AO33: N/A | AP33: pbbnco@gmail.com
A34: 33 | B34: OSEC-DOHB-MDSP2-270015-2020 | C34: Medical Specialist II (Anesthesiologist) | D34: Anesthesiologist | E34: Medical Specialist II | F34: Anesthesiology Department | G34: Physician | H34: Medical Division | I34: 23 | J34: =LOOKUP(Table1[[#This Row],[SALARY GRADE]],{1,2,3,4,5,6,7,8,9,10,11,12,13,14,15,16,17,18,19,20,21,22,23,24,25,26,27,28,29,30,31,32,33},{14364,15522,16486,17506,18581,19716,20914,22423,24329,26917,31705,33947,36125,38764,42178,45694,49562,53818,59153,66052,73303,81796,91306,102603,116643,131807,148940,167129,187531,210718,300961,356237,449157}) -> 91306 | K34: 2nd | L34: =IF(Table1[[#This Row],[LAST]]="","Unfilled","Filled") -> Filled | M34: Valenzuela | N34: Jona-Patricia | O34: Ravelo | Q34: 33076 | R34: 46113 | S34: 46113 | T34: 46113 | U34: Married | V34: Female | W34: =DATEDIF(Q34,TODAY(),"Y") -> 36 | X34: =IF(ABS(Table1[[#This Row],[AGE]])>59,"60 and above",IF(ABS(Table1[[#This Row],[AGE]])>49,"50-59",IF(ABS(Table1[[#This Row],[AGE]])>39,"40-49",IF(ABS(Table1[[#This Row],[AGE]])>29,"30-39",IF(ABS(Table1[[#This Row],[AGE]])>19,"20-29",""))))) -> 30-39 | Y34: Mandaluyong City, Metro Manila | Z34: 2628 Arellano Avenue | AA34: Brgy. 765, Sta. Ana | AB34: Manila City | AC34: Metro Manila | AD34: 1009 | AE34: Doctor of Medicine | AF34: Medicine | AG34: RA 1080 | AH34: 0144265 | AI34: 46590 | AJ34: N/A | AK34: 1210-2231-4651 | AL34: 0205-8033-9624 | AM34: 419-851-139 | AN34: 0927-217-0820 | AO34: N/A | AP34: jpfravelo@gmail.com
A35: 34 | B35: OSEC-DOHB-MDSP2-270016-2020 | C35: Medical Specialist II (Surgeon) | D35: Surgeon | E35: Medical Specialist II | F35: Surgery Department | G35: Physician | H35: Medical Division | I35: 23 | J35: =LOOKUP(Table1[[#This Row],[SALARY GRADE]],{1,2,3,4,5,6,7,8,9,10,11,12,13,14,15,16,17,18,19,20,21,22,23,24,25,26,27,28,29,30,31,32,33},{14364,15522,16486,17506,18581,19716,20914,22423,24329,26917,31705,33947,36125,38764,42178,45694,49562,53818,59153,66052,73303,81796,91306,102603,116643,131807,148940,167129,187531,210718,300961,356237,449157}) -> 91306 | K35: 2nd | L35: =IF(Table1[[#This Row],[LAST]]="","Unfilled","Filled") -> Filled | M35: Hernandez-Roa | N35: Gerlie | O35: Ocampo | Q35: 31595 | R35: 44960 | S35: 44960 | T35: 44960 | U35: Married | V35: Female | W35: =DATEDIF(Q35,TODAY(),"Y") -> 40 | X35: =IF(ABS(Table1[[#This Row],[AGE]])>59,"60 and above",IF(ABS(Table1[[#This Row],[AGE]])>49,"50-59",IF(ABS(Table1[[#This Row],[AGE]])>39,"40-49",IF(ABS(Table1[[#This Row],[AGE]])>29,"30-39",IF(ABS(Table1[[#This Row],[AGE]])>19,"20-29",""))))) -> 40-49 | Y35: Cavite City | Z35: 51 Antioch Remeville | AA35: Magdiwang | AB35: Noveleta | AC35: Cavite | AD35: 4105 | AE35: Doctor of Medicine | AF35: Medicine | AG35: RA 1080 | AH35: 0127428 | AI35: 46205 | AJ35: 2004921701 | AK35: 1211-8923-0589 | AL35: 0805-0834-5552 | AM35: 287-610-993 | AN35: 0968-366-5442 | AO35: N/A | AP35: gerlmd1216@gmail.com
A36: 35 | B36: OSEC-DOHB-MDSP2-270017-2020 | C36: Medical Specialist II (Obstretician) | D36: Obstetrician | E36: Medical Specialist II | F36: Obstetrics-Gynecology Department | G36: Physician | H36: Medical Division | I36: 23 | J36: =LOOKUP(Table1[[#This Row],[SALARY GRADE]],{1,2,3,4,5,6,7,8,9,10,11,12,13,14,15,16,17,18,19,20,21,22,23,24,25,26,27,28,29,30,31,32,33},{14364,15522,16486,17506,18581,19716,20914,22423,24329,26917,31705,33947,36125,38764,42178,45694,49562,53818,59153,66052,73303,81796,91306,102603,116643,131807,148940,167129,187531,210718,300961,356237,449157}) -> 91306 | K36: 2nd | L36: =IF(Table1[[#This Row],[LAST]]="","Unfilled","Filled") -> Filled | M36: Montaña | N36: Justine Erika | O36: Tan | Q36: 32560 | R36: 45701 | S36: 45701 | T36: 45701 | U36: Single | V36: Female | W36: =DATEDIF(Q36,TODAY(),"Y") -> 37 | X36: =IF(ABS(Table1[[#This Row],[AGE]])>59,"60 and above",IF(ABS(Table1[[#This Row],[AGE]])>49,"50-59",IF(ABS(Table1[[#This Row],[AGE]])>39,"40-49",IF(ABS(Table1[[#This Row],[AGE]])>29,"30-39",IF(ABS(Table1[[#This Row],[AGE]])>19,"20-29",""))))) -> 30-39 | Y36: Manila | Z36: Block 2 Lot 49 F. Chioco Granwood Villas | AA36: Holy Spirit | AB36: Quezon City | AC36: Metro Manila | AD36: 1127 | AE36: Doctor of Medicine | AF36: Medicine | AG36: RA 1080 | AH36: 0136002 | AI36: 46074 | AJ36: 2005343648 | AK36: 1212-1557-8448 | AL36: 0202-5656-2139 | AM36: 476-358-638 | AN36: 0917-624-9370 | AO36: 516-1603 | AP36: justineerikamontana0221@gmail.com
A37: 36 | B37: OSEC-DOHB-MDSP2-270015-2022 | C37: Medical Specialist II (OPD) | D37: Family Medicine | E37: Medical Specialist II | F37: Outpatient Department | G37: Physician | H37: Medical Division | I37: 23 | J37: =LOOKUP(Table1[[#This Row],[SALARY GRADE]],{1,2,3,4,5,6,7,8,9,10,11,12,13,14,15,16,17,18,19,20,21,22,23,24,25,26,27,28,29,30,31,32,33},{14364,15522,16486,17506,18581,19716,20914,22423,24329,26917,31705,33947,36125,38764,42178,45694,49562,53818,59153,66052,73303,81796,91306,102603,116643,131807,148940,167129,187531,210718,300961,356237,449157}) -> 91306 | K37: 2nd | L37: =IF(Table1[[#This Row],[LAST]]="","Unfilled","Filled") -> Filled | M37: Bingco | O37: Vice Supetran, Resigned
A38: 37 | B38: OSEC-DOHB-NUR6-270011-2020 | C38: Nurse VI | E38: Nurse VI | F38: Office of the Chief Nurse | G38: Nurse | H38: Nursing Division | I38: 22 | J38: =LOOKUP(Table1[[#This Row],[SALARY GRADE]],{1,2,3,4,5,6,7,8,9,10,11,12,13,14,15,16,17,18,19,20,21,22,23,24,25,26,27,28,29,30,31,32,33},{14364,15522,16486,17506,18581,19716,20914,22423,24329,26917,31705,33947,36125,38764,42178,45694,49562,53818,59153,66052,73303,81796,91306,102603,116643,131807,148940,167129,187531,210718,300961,356237,449157}) -> 81796 | K38: 2nd | L38: =IF(Table1[[#This Row],[LAST]]="","Unfilled","Filled") -> Filled | M38: Atmosfera | N38: Jonathan | O38: Trinidad | Q38: 30493 | R38: 39449 | S38: 44348 | T38: 46065 | U38: Married | V38: Male | W38: =DATEDIF(Q38,TODAY(),"Y") -> 43 | X38: =IF(ABS(Table1[[#This Row],[AGE]])>59,"60 and above",IF(ABS(Table1[[#This Row],[AGE]])>49,"50-59",IF(ABS(Table1[[#This Row],[AGE]])>39,"40-49",IF(ABS(Table1[[#This Row],[AGE]])>29,"30-39",IF(ABS(Table1[[#This Row],[AGE]])>19,"20-29",""))))) -> 40-49 | Y38: Dasmariñas City, Cavite | Z38: #3 Medina Ville | AA38: San Jose | AB38: Dasmariñas City | AC38: Cavite | AD38: 4114 | AE38: College Graduate | AF38: BS Nursing | AG38: RA 1080 | AH38: 0429365 | AI38: 45834 | AJ38: 2003464775 | AK38: 1030-0107-5387 | AL38: 0800-0111-6103 | AM38: 261-262-502 | AN38: 0999-575-3374 | AO38: N/A | AP38: atmosferajonathan@yahoo.com
A39: 38 | B39: OSEC-DOHB-SADOF-270010-2020 | C39: Supervising Administrative Officer | E39: Supervising Administrative Officer | F39: Office of the Supervising Administrative Officer | G39: Administrative Officer | H39: Hospital Operation and Patient Support Division | I39: 22 | J39: =LOOKUP(Table1[[#This Row],[SALARY GRADE]],{1,2,3,4,5,6,7,8,9,10,11,12,13,14,15,16,17,18,19,20,21,22,23,24,25,26,27,28,29,30,31,32,33},{14364,15522,16486,17506,18581,19716,20914,22423,24329,26917,31705,33947,36125,38764,42178,45694,49562,53818,59153,66052,73303,81796,91306,102603,116643,131807,148940,167129,187531,210718,300961,356237,449157}) -> 81796 | K39: 2nd | L39: =IF(Table1[[#This Row],[LAST]]="","Unfilled","Filled") -> Filled | M39: Gejon | N39: Allyn | O39: Matalubos | Q39: 27998 | R39: 37074 | S39: 38642 | T39: 44320 | U39: Married | V39: Female | W39: =DATEDIF(Q39,TODAY(),"Y") -> 49 | X39: =IF(ABS(Table1[[#This Row],[AGE]])>59,"60 and above",IF(ABS(Table1[[#This Row],[AGE]])>49,"50-59",IF(ABS(Table1[[#This Row],[AGE]])>39,"40-49",IF(ABS(Table1[[#This Row],[AGE]])>29,"30-39",IF(ABS(Table1[[#This Row],[AGE]])>19,"20-29",""))))) -> 40-49 | Y39: Pigcawayan, N. Cotabato | Z39: B N.17 L9 | AA39: Immanuel I | AB39: Dasmariñas City | AC39: Cavite | AD39: 4114 | AE39: Master's Degree | AF39: Master's in Management | AG39: CSC - Professional | AH39: N/A | AI39: N/A | AJ39: 2001157315 | AK39: 0080-8284-2007 | AL39: 1900-0608-1295 | AM39: 914-330-684 | AN39: 0905-573-0153 | AO39: N/A | AP39: agejon@yahoo.com
A40: 39 | B40: OSEC-DOHB-MDOF3-270003-2020 | C40: Medical Officer III (Pedia) | D40: Pediatrician | E40: Medical Officer III | F40: Pediatrics Department | G40: Physician | H40: Medical Division | I40: 21 | J40: =LOOKUP(Table1[[#This Row],[SALARY GRADE]],{1,2,3,4,5,6,7,8,9,10,11,12,13,14,15,16,17,18,19,20,21,22,23,24,25,26,27,28,29,30,31,32,33},{14364,15522,16486,17506,18581,19716,20914,22423,24329,26917,31705,33947,36125,38764,42178,45694,49562,53818,59153,66052,73303,81796,91306,102603,116643,131807,148940,167129,187531,210718,300961,356237,449157}) -> 73303 | K40: 2nd | L40: =IF(Table1[[#This Row],[LAST]]="","Unfilled","Filled") -> Filled | M40: Barron | N40: Emmanuel John | O40: Valenzuela | Q40: 32455 | R40: 45663 | S40: 45663 | T40: 45663 | U40: Single | V40: Male | W40: =DATEDIF(Q40,TODAY(),"Y") -> 37 | X40: =IF(ABS(Table1[[#This Row],[AGE]])>59,"60 and above",IF(ABS(Table1[[#This Row],[AGE]])>49,"50-59",IF(ABS(Table1[[#This Row],[AGE]])>39,"40-49",IF(ABS(Table1[[#This Row],[AGE]])>29,"30-39",IF(ABS(Table1[[#This Row],[AGE]])>19,"20-29",""))))) -> 30-39 | Y40: Lipa City, Batangas | Z40: Block 11, Lot 74 Via Mantua, Ponticelli 1 Subdivision | AA40: Molino III | AB40: Bacoor City | AC40: Cavite | AD40: 4102 | AE40: Doctor of Medicine | AF40: Medicine | AG40: RA 1080 | AH40: 0130601 | AI40: 46699 | AJ40: 2004973679 | AK40: 1211-8412-5957 | AL40: 0900-0094-9581 | AM40: 464-909-385 | AN40: 0933-826-2997 | AO40: N/A | AP40: barron_ej@yahoo.com
...

Sheet DASHBOARD
V1: Republic of the Philippines
V2: Department of Health | AS2: Table 4. Distribution of Permanent Employees by Division Assignment and Age Group
V3: SOUTHERN TAGALOG REGIONAL HOSPITAL | AS3: as of June 5, 2024
V4: Brgy. Habay II, City of Bacoor, Cavite
V5: Tel No. (046) 884-2810 / (046)435-1071 / (046)435-0742
V6: Email: HRMS@strh.doh.gov.ph
B8: Table 1. Status of Plantilla Position by Division | X8: Table 2. Distribution of Permanent Employees by Level, Division Assignment and Sex
B9: as of | K9: =TODAY() -> 46252 | AB9: as of | AD9: =TODAY() -> 46252
B22: Table 3. Distribution of Permanent Employees by CADRE
B23: as of | U23: =TODAY() -> 46252
B51: Prepared by: | Z51: Noted by:
B54: CEPRIANO EDUARDO J. MALAYA, MMHoA | Z54: WILMA P. BAYAS, MMHoA
B55: Administrative Assistant II | Z55: Administrative Officer V / HRMO III | AZ55: 7
B57: Table 4. Distribution of Permanent Employees by Position
B58: as of | U58: =TODAY() -> 46252
B100: Prepared by: | Z100: Noted by:
B104: CEPRIANO EDUARDO J. MALAYA, MMHoA | Z104: WILMA P. BAYAS, MMHoA
B105: Administrative Assistant II | Z105: Administrative Officer V / HRMO III
B148: Prepared by: | Z148: Noted by:
B153: CEPRIANO EDUARDO J. MALAYA, MMHoA | Z153: WILMA P. BAYAS, MMHoA
B154: Administrative Assistant II | Z154: Administrative Officer V / HRMO III

Sheet FormulaSheet
A4: Divisions | B4: Position | D4: Total | N4: Divisions | O4: Level | P4: SEX | R4: Total | T4: Divisions | U4: Level | X4: SEX | Z4: Total
B5: Filled | C5: Unfilled | O5: 1st | P5: Male | Q5: Female | U5: 1st | V5: 2nd | W5: 3rd | X5: Male | Y5: Female
A6: Hospital Operation and Patient Support Division | B6: =COUNTIFS(Table1[26],FormulaSheet!$A6,Table1[FILLED&UNFILLED],FormulaSheet!$B5) -> 52 | C6: =COUNTIFS(Table1[26],FormulaSheet!$A6,Table1[FILLED&UNFILLED],FormulaSheet!$C5) -> 2 | D6: =SUM(B6:C6) -> 54 | N6: Hospital Operation and Patient Support Division | O6: =COUNTIFS(Table1[26],FormulaSheet!N6,Table1[Level2],FormulaSheet!O5) -> 33 | P6: =COUNTIFS(Table1[26],FormulaSheet!N6,Table1[GENDER],FormulaSheet!P5,Table1[Level2],FormulaSheet!O5) -> 16 | Q6: =COUNTIFS(Table1[26],FormulaSheet!N6,Table1[GENDER],FormulaSheet!Q5,Table1[Level2],FormulaSheet!O5) -> 15 | R6: =SUM(P6:Q6) -> 31 | T6: Hospital Operation and Patient Support Division | U6: =O6 -> 33 | V6: =O14 -> 21 | W6: 0 | X6: =P6+P14 -> 23 | Y6: =Q6+Q14 -> 29 | Z6: =SUM(X6:Y6) -> 52
A7: Nursing Division | B7: =COUNTIFS(Table1[26],FormulaSheet!$A7,Table1[FILLED&UNFILLED],FormulaSheet!$B5) -> 138 | C7: =COUNTIFS(Table1[26],FormulaSheet!$A7,Table1[FILLED&UNFILLED],FormulaSheet!$C5) -> 3 | D7: =SUM(B7:C7) -> 141 | N7: Nursing Division | O7: =COUNTIFS(Table1[26],FormulaSheet!N7,Table1[Level2],FormulaSheet!O5) -> 42 | P7: =COUNTIFS(Table1[26],FormulaSheet!N7,Table1[GENDER],FormulaSheet!P5,Table1[Level2],FormulaSheet!O5) -> 12 | Q7: =COUNTIFS(Table1[26],FormulaSheet!N7,Table1[GENDER],FormulaSheet!Q5,Table1[Level2],FormulaSheet!O5) -> 30 | R7: =SUM(P7:Q7) -> 42 | T7: Nursing Division | U7: =O7 -> 42 | V7: =O15 -> 99 | W7: 0 | X7: =P7+P15 -> 37 | Y7: =Q7+Q15 -> 101 | Z7: =SUM(X7:Y7) -> 138
